Workbook

Sheet Relatório Indicadores 21
E10: Indicador | F10: Jan | G10: Fev | H10: Mar | I10: Abr | J10: Mai | K10: Jun | L10: Jul | M10: Ago | N10: Set | O10: Out | P10: Nov | Q10: Dez
E11: Base Vidas | F11: 57600 | G11: 57436 | H11: 61323 | I11: 62869 | J11: 64535 | K11: 65797 | L11: 68499 | M11: 70242 | N11: 70298 | O11: 69787 | P11: 68757 | Q11: 68911
E12: Base Dental | F12: 521 | G12: 526 | H12: 537 | I12: 548 | J12: 555 | K12: 566 | L12: 802 | M12: 1181 | N12: 1330 | O12: 1333 | P12: 1365 | Q12: 1461
E13: Base Saúde | F13: 57079 | G13: 56910 | H13: 60786 | I13: 62321 | J13: 63980 | K13: 65231 | L13: 67697 | M13: 69061 | N13: 68968 | O13: 68454 | P13: 67392 | Q13: 67450
E14: Vidas canceladas | F14: 2348 | G14: 2792 | H14: 2503 | I14: 2244 | J14: 2266 | K14: 2508 | L14: 3026 | M14: 3304 | N14: 3960 | O14: 5014 | P14: 4112 | Q14: 4024
E15: Retenção | F15: 276 | G15: 367 | H15: 226 | I15: 176 | J15: 195 | K15: 284 | L15: 558 | M15: 387 | N15: 735 | O15: 844 | P15: 748 | Q15: 946
E16: % cancelamento | F16: 0.041545757 | G16: 0.048472222 | H16: 0.04357894 | I16: 0.036593122 | J16: 0.036043201 | K16: 0.038862633 | L16: 0.045989939 | M16: 0.048234281 | N16: 0.056376527 | O16: 0.071324931 | P16: 0.058922149 | Q16: 0.05852495
E17: Cancel. por Inadimplência | F17: 637 | G17: 887 | H17: 822 | I17: 786 | J17: 942 | K17: 887 | L17: 709 | M17: 808 | N17: 998 | O17: 1323 | P17: 1356 | Q17: 1504
E18: Cancel. solicitação cliente | F18: 1399 | G18: 1628 | H18: 1243 | I18: 1106 | J18: 1073 | K18: 1246 | L18: 1791 | M18: 1817 | N18: 1508 | O18: 2393 | P18: 2280 | Q18: 1771
E19: Cancel. Solicitado OPS | F19: 218 | G19: 139 | H19: 114 | I19: 191 | J19: 173 | K19: 227 | L19: 392 | M19: 533 | N19: 1350 | O19: 1164 | P19: 324 | Q19: 612
E20: Exclusão de dependente (A partir de Maio) | F20: - | G20: - | H20: - | I20: - | J20: 31 | K20: 34 | L20: 26 | M20: 19 | N20: 19 | O20: 17 | P20: 29 | Q20: 34
E21: Falecimento (A partir de Maio) | F21: - | G21: - | H21: - | I21: - | J21: 13 | K21: 7 | L21: 10 | M21: 7 | N21: 2 | O21: 6 | P21: 12 | Q21: 8
E22: Outros (A partir de Maio) | F22: 94 | G22: 138 | H22: 324 | I22: 161 | J22: 34 | K22: 107 | L22: 98 | M22: 120 | N22: 83 | O22: 111 | P22: 111 | Q22: 95
E23: Faturamento Emitido | F23: 38042748 | G23: 38099984 | H23: 39967218 | I23: 41023639 | J23: 41689102 | K23: 43041830 | L23: 46311488 | M23: 47292638 | N23: 46814585 | O23: 46397911 | P23: 46395074 | Q23: 46006217
E24: Faturamento Recebido | F24: 37560161 | G24: 37663473 | H24: 39483456 | I24: 40571025 | J24: 41255548 | K24: 40195160 | L24: 42794550 | M24: 43880353 | N24: 43324679 | O24: 41593979 | P24: 42411622 | Q24: 40802541
E25: Inadimplência | F25: 0.01268539 | G25: 0.011456985 | H25: 0.012103964 | I25: 0.011032995 | J25: 0.010399676 | K25: 0.066137301 | L25: 0.075940926 | M25: 0.072152569 | N25: 0.074547413 | O25: 0.1035377 | P25: 0.085859381 | Q25: 0.1131081
E26: Vendas | F26: 1720 | G26: 3116 | H26: 5720 | I26: 4355 | J26: 3364 | K26: 3679 | L26: 5677 | M26: 5119 | N26: 4060 | O26: 4792 | P26: 4272 | Q26: 3319
E27: Ticket médio | F27: 660.46437 | G27: 663.34675 | H27: 651.74922 | I27: 652.52571 | J27: 645.99212 | K27: 654.16099 | L27: 676.08998 | M27: 673.28148 | N27: 665.94476 | O27: 664.85035 | P27: 674.76874 | Q27: 667.6179
E28: Comissão Concessionárias | F28: 791138.97 | G28: 785044.32 | H28: 891683.76 | I28: 1562071.5 | J28: 1357926 | K28: 1136660.3 | L28: 1270749.4 | M28: 1474927.1 | N28: 1414873.8 | O28: 1174586.3 | P28: 1294079.8 | Q28: 1563510.4
E29: Bonificação Corretores/supervisores | F29: 492989.45 | G29: 716100.76 | H29: 1359268 | I29: 1970200 | J29: 2021250 | K29: 1300590 | L29: 1527848.9 | M29: 1736614.7 | N29: 1507306.5 | O29: 1213192.4 | P29: 1429715.3 | Q29: 1672830
E31: Indicador | F31: Jan | G31: Fev | H31: Mar | I31: Abr | J31: Mai | K31: Jun | L31: Jul | M31: Ago | N31: Set | O31: Out | P31: Nov | Q31: Dez
E32: Base Vidas | F32: 5699 | G32: 5557 | H32: 5452 | I32: 5478 | J32: 5555 | K32: 5561 | L32: 8368 | M32: 9844 | N32: 10312 | O32: 10617 | P32: 10554 | Q32: 10530
E33: Base Dental | F33: 0 | G33: 0 | H33: 0 | I33: 0 | J33: 0 | K33: 0 | L33: 0 | M33: 0 | N33: 0 | O33: 0 | P33: 0 | Q33: 0
E34: Base Saúde | F34: 5699 | G34: 5557 | H34: 5452 | I34: 5478 | J34: 5555 | K34: 5561 | L34: 8368 | M34: 9844 | N34: 10312 | O34: 10617 | P34: 10554 | Q34: 10530
E35: Vidas canceladas | F35: 268 | G35: 346 | H35: 375 | I35: 306 | J35: 280 | K35: 272 | L35: 352 | M35: 369 | N35: 640 | O35: 666 | P35: 603 | Q35: 611
E36: Retenção | F36: 27 | G36: 37 | H36: 22 | I36: 26 | J36: 28 | K36: 17 | L36: 53 | M36: 161 | N36: 344 | O36: 276 | P36: 99 | Q36: 88
E37: % cancelamento | F37: 0.046294697 | G37: 0.060712406 | H37: 0.067482455 | I37: 0.056126192 | J37: 0.051113545 | K37: 0.048964896 | L37: 0.063297968 | M37: 0.044096558 | N37: 0.065014222 | O37: 0.06458495 | P37: 0.056795705 | Q37: 0.057892742
E38: Cancel. por Inadimplência | F38: 101 | G38: 136 | H38: 150 | I38: 113 | J38: 122 | K38: 114 | L38: 97 | M38: 85 | N38: 295 | O38: 389 | P38: 331 | Q38: 5
E39: Cancel. solicitação cliente | F39: 125 | G39: 152 | H39: 158 | I39: 147 | J39: 118 | K39: 104 | L39: 186 | M39: 198 | N39: 234 | O39: 188 | P39: 181 | Q39: 1
E40: Cancel. Solicitado OPS | F40: 30 | G40: 46 | H40: 35 | I40: 38 | J40: 30 | K40: 29 | L40: 43 | M40: 48 | N40: 76 | O40: 59 | P40: 71 | Q40: 346
E41: Exclusão de dependente (A partir de Maio) | F41: 0 | G41: 0 | H41: 0 | I41: 0 | J41: 6 | K41: 4 | L41: 3 | M41: 4 | N41: 5 | O41: 3 | P41: 3 | Q41: 24
E42: Falecimento (A partir de Maio) | F42: 0 | G42: 0 | H42: 0 | I42: 0 | J42: 0 | K42: 2 | L42: 0 | M42: 2 | N42: 2 | O42: 2 | P42: 3 | Q42: 59
E43: Outros (A partir de Maio) | F43: 12 | G43: 12 | H43: 32 | I43: 8 | J43: 4 | K43: 19 | L43: 23 | M43: 32 | N43: 28 | O43: 25 | P43: 14 | Q43: 176
... E50: Bonificação Corretores/supervisores | F50: 13045.25 | G50: 15095.82 | H50: 47492.86 | I50: 60373.7 | J50: 110643.91 | K50: 79835.63 | L50: 81115.03 | M50: 811669.51 | N50: 553813.86 | O50: 270997.04 | P50: 194673.7 | Q50: 125219.51
E52: Indicador | F52: Jan | G52: Fev | H52: Mar | I52: Abr | J52: Mai | K52: Jun | L52: Jul | M52: Ago | N52: Set | O52: Out | P52: Nov | Q52: Dez | T52: .
E53: Base Vidas | F53: 7139 | G53: 6910 | H53: 6656 | I53: 6392 | J53: 6207 | K53: 6058 | L53: 5899 | M53: 5812 | N53: 4751 | O53: 28 | P53: 41 | Q53: =SUM(Q54:Q55) -> 40
E54: Base Dental | F54: 0 | G54: 0 | H54: 0 | I54: 0 | J54: 0 | K54: 0 | L54: 0 | M54: 0 | N54: 0 | O54: 0 | P54: 0 | Q54: 0
E55: Base Saúde | F55: 7131 | G55: 6901 | H55: 6647 | I55: 6383 | J55: 6198 | K55: 6050 | L55: 5890 | M55: 5803 | N55: 4742 | O55: 28 | P55: 41 | Q55: 40
E56: Vidas canceladas | F56: 345 | G56: 344 | H56: 414 | I56: 307 | J56: =SUM(J59:J64) -> 291 | K56: =SUM(K59:K64) -> 231 | L56: =SUM(L59:L64) -> 248 | M56: =SUM(M59:M64) -> 272 | N56: =SUM(N59:N64) -> 1056 | O56: =SUM(O59:O64) -> 4689 | P56: =SUM(P59:P64) -> 3 | Q56: =SUM(Q59:Q64) -> 5
E57: Retenção | F57: 22 | G57: 14 | H57: 6 | I57: 6 | J57: 11 | K57: 17 | L57: 12 | M57: 6 | N57: 4 | O57: 1 | P57: 0 | Q57: 0
...

Sheet Relatório Indicadores 22
E10: Indicador | F10: Jan | G10: Fev | H10: Mar | I10: Abr | J10: Mai | K10: Jun | L10: Jul | M10: Ago | N10: Set | O10: Out | P10: Nov | Q10: Dez
F11: #REF! | G11: =F13-G16+G28 -> 66456 | H11: =G13-H16+H28 -> 62722 | I11: =H13-I16+I28 -> 59820 | J11: =I13-J16+J28 -> 57356 | K11: =J13-K16+K28 -> 55002 | L11: =K13-L16+L28 -> 49254 | M11: =L13-M16+M28 -> 45055 | N11: =M13-N16+N28 -> 42461 | ... P11: =O13-P16+P28 -> 39479
F12: =F13-F11 -> #REF! | G12: =G13-G11 -> 918 | H12: =H13-H11 -> -87 | I12: =I13-I11 -> 41 | J12: =J13-J11 -> 79 | K12: =K13-K11 -> -177 | L12: =L13-L11 -> -691 | M12: =M13-M11 -> -26 | ... P12: =P13-P11 -> -45
E13: Base Vidas | F13: =SUM(F14:F15) -> 67476 | G13: =SUM(G14:G15) -> 67374 | H13: =SUM(H14:H15) -> 62635 | I13: =SUM(I14:I15) -> 59861 | J13: =SUM(J14:J15) -> 57435 | K13: =SUM(K14:K15) -> 54825 | L13: =SUM(L14:L15) -> 48563 | M13: =SUM(M14:M15) -> 45029 | ... Q13: =SUM(Q14:Q15) -> 38757
E14: Base Dental | F14: 1603 | G14: 1616 | H14: 1685 | I14: 1786 | J14: 1729 | K14: 1747 | L14: 1810 | M14: 1785 | N14: 1644 | O14: 1570 | P14: 1553 | Q14: 1541
E15: Base Saúde | F15: 65873 | G15: 65758 | H15: 60950 | I15: 58075 | J15: 55706 | K15: 53078 | L15: 46753 | M15: 43244 | N15: 40635 | O15: 38884 | P15: 37881 | Q15: 37216
E16: Vidas canceladas | F16: =SUM(F19:F24) -> 4721 | G16: =SUM(G19:G24) -> 3855 | H16: =SUM(H19:H24) -> 7570 | I16: =SUM(I19:I24) -> 5714 | J16: =SUM(J19:J24) -> 4131 | K16: =SUM(K19:K24) -> 4320 | L16: =SUM(L19:L24) -> 8602 | M16: =SUM(M19:M24) -> 5505 | ... Q16: =SUM(Q19:Q24) -> 1528
E17: Retenção | F17: 1015 | G17: 773 | H17: 845 | I17: 496 | J17: 714 | K17: 1040 | L17: 1210 | M17: 696 | N17: 574 | O17: 433 | P17: 686 | Q17: 364
E18: % cancelamento | F18: 0.068508656 | G18: =IFERROR((G16/F13),0) -> 0.057131425 | H18: =IFERROR((H16/G13),0) -> 0.11235788 | I18: =IFERROR((I16/H13),0) -> 0.09122695 | J18: =IFERROR((J16/I13),0) -> 0.069009873 | K18: =IFERROR((K16/J13),0) -> 0.075215461 | L18: =IFERROR((L16/K13),0) -> 0.15689922 | M18: =IFERROR((M16/L13),0) -> 0.11335791 | N18: =IFERROR((N16/M13),0) -> 0.088898266 | ... Q18: =IFERROR((Q16/P13),0) -> 0.038748288
E19: Cancel. por Inadimplência | F19: 1490 | G19: 1232 | H19: 1522 | I19: 1583 | J19: 1923 | K19: 1833 | L19: 1365 | M19: 1283 | N19: 2316 | O19: 879 | P19: 709 | Q19: 530
E20: Cancel. solicitação cliente | F20: 2453 | G20: 1674 | H20: 3496 | I20: 2562 | J20: 1354 | K20: 1787 | L20: 4259 | M20: 2868 | N20: 1154 | O20: 757 | P20: 643 | Q20: 616
E21: Cancel. Solicitado OPS | F21: 639 | G21: 850 | H21: 2390 | I21: 1510 | J21: 809 | K21: 655 | L21: 2960 | M21: 1305 | N21: 439 | O21: 312 | P21: 272 | Q21: 213
E22: Exclusão de dependente | F22: 22 | G22: 25 | H22: 52 | I22: - | L22: 0
E23: Falecimento | F23: 17 | G23: 13 | H23: 3 | I23: 0 | J23: 0 | K23: 7 | L23: 2 | M23: 9 | N23: 3 | O23: 4 | P23: 5 | Q23: 14
E24: Outros | F24: 100 | G24: 61 | H24: 107 | I24: 59 | J24: 45 | K24: 38 | L24: 16 | M24: 40 | N24: 91 | O24: 30 | P24: 39 | Q24: 155
E25: Faturamento Emitido | F25: 44842301 | G25: 44499708 | H25: 42810223 | I25: 43422255 | J25: 38377906 | K25: 36818173 | L25: 38647053 | M25: 35285221 | N25: 33306251 | O25: 32145011 | P25: 31596726 | Q25: 31022320
E26: Faturamento Recebido | F26: 41786730 | G26: 39328844 | H26: 38832051 | I26: 35171965 | J26: 32932381 | K26: 33083404 | L26: 32460565 | M26: 31568060 | N26: 29995521 | O26: 29257104 | P26: 28792771 | Q26: 28596266
E27: Inadimplência | F27: =IFERROR((1-F26/F25),0) -> 0.068140355 | G27: =IFERROR((1-G26/G25),0) -> 0.11619995 | H27: =IFERROR((1-H26/H25),0) -> 0.092925738 | I27: =IFERROR((1-I26/I25),0) -> 0.1900014 | J27: =IFERROR((1-J26/J25),0) -> 0.14189219 | K27: =IFERROR((1-K26/K25),0) -> 0.10143819 | L27: =IFERROR((1-L26/L25),0) -> 0.16007656 | M27: =IFERROR((1-M26/M25),0) -> 0.10534612 | ... Q27: =IFERROR((1-Q26/Q25),0) -> 0.078203516
E28: Vendas | F28: 3246 | G28: 2835 | H28: 2918 | I28: 2899 | J28: 1626 | K28: 1887 | L28: 3031 | M28: 1997 | N28: 1435 | O28: 376 | P28: 693 | Q28: 864
E29: Ticket médio | F29: =IFERROR(F25/F13,0) -> 664.56667 | G29: =IFERROR(G25/G13,0) -> 660.48785 | H29: =IFERROR(H25/H13,0) -> 683.48723 | I29: =IFERROR(I25/I13,0) -> 725.38472 | J29: =IFERROR(J25/J13,0) -> 668.1972 | K29: =IFERROR(K25/K13,0) -> 671.55811 | L29: =IFERROR(L25/L13,0) -> 795.81271 | M29: =IFERROR(M25/M13,0) -> 783.61103 | ... Q29: =IFERROR(Q25/Q13,0) -> 800.43141
E30: Comissão Concessionárias | F30: 1200286.8 | G30: 1059007.7 | H30: 1091242.7 | I30: 1032842.1 | J30: 833075.13 | K30: 782584.1 | L30: 745961.59 | M30: 733919.95 | N30: 658967.1 | O30: 629408.03 | P30: 525435.87 | Q30: 546779.85
E31: Bonificação Corretores/supervisores | F31: 721759.33 | G31: 721759.33 | H31: 614759.94 | I31: 514687.03 | J31: 496574.37 | K31: 605079.98 | L31: 546967.19 | M31: 478527.34 | N31: 376181.55 | O31: 173309.88 | P31: 210750
F33: #REF! | G33: =F36-G39+G51 -> 10371 | H33: =G36-H39+H51 -> 10860 | I33: =H36-I39+I51 -> 11470 | J33: =I36-J39+J51 -> 12115 | K33: =J36-K39+K51 -> 11874 | L33: =K36-L39+L51 -> 11132 | M33: =L36-M39+M51 -> 11130 | N33: =M36-N39+N51 -> 10733 | ... P33: =O36-P39+P51 -> 10465
F34: =F36-F33 -> #REF! | G34: =G36-G33 -> -41 | H34: =H36-H33 -> -29 | I34: =I36-I33 -> 43 | J34: =J36-J33 -> 48 | K34: =K36-K33 -> -5 | L34: =L36-L33 -> -57 | M34: =M36-M33 -> 21 | ... P34: =P36-P33 -> -3
E35: Indicador | F35: Jan | G35: Fev | H35: Mar | I35: Abr | J35: Mai | K35: Jun | L35: Jul | M35: Ago | N35: Set | O35: Out | P35: Nov | Q35: Dez
E36: Base Vidas | F36: =SUM(F37:F38) -> 10494 | G36: =SUM(G37:G38) -> 10330 | H36: =SUM(H37:H38) -> 10831 | I36: =SUM(I37:I38) -> 11513 | J36: =SUM(J37:J38) -> 12163 | K36: =SUM(K37:K38) -> 11869 | L36: =SUM(L37:L38) -> 11075 | M36: =SUM(M37:M38) -> 11151 | ... Q36: =SUM(Q37:Q38) -> 10565
E37: Base Dental | F37: 0 | G37: 0 | H37: 0 | I37: 0 | J37: 0 | K37: 0 | L37: 0 | M37: 0 | N37: 0 | O37: 0 | P37: 0 | Q37: 0
E38: Base Saúde | F38: 10494 | G38: 10330 | H38: 10831 | I38: 11513 | J38: 12163 | K38: 11869 | L38: 11075 | M38: 11151 | N38: 10741 | O38: 10655 | P38: 10462 | Q38: 10565
E39: Vidas canceladas | F39: =SUM(F42:F47) -> 597 | G39: =SUM(G42:G47) -> 652 | H39: =SUM(H42:H47) -> 574 | I39: =SUM(I42:I47) -> 569 | J39: =SUM(J42:J47) -> 593 | K39: =SUM(K42:K47) -> 761 | L39: =SUM(L42:L47) -> 1170 | M39: =SUM(M42:M47) -> 1027 | ... Q39: =SUM(Q42:Q47) -> 617
E40: Retenção | F40: 41 | G40: 41 | H40: 21 | I40: 28 | J40: 34 | K40: 64 | L40: 110 | M40: 100 | N40: 103 | O40: 41 | P40: 164 | Q40: 420
E41: % cancelamento | F41: 0.056695157 | G41: =IFERROR((G39/F36),0) -> 0.062130741 | H41: =IFERROR((H39/G36),0) -> 0.055566312 | I41: =IFERROR((I39/H36),0) -> 0.052534392 | J41: =IFERROR((J39/I36),0) -> 0.051506992 | K41: =IFERROR((K39/J36),0) -> 0.062566801 | L41: =IFERROR((L39/K36),0) -> 0.098576123 | M41: =IFERROR((M39/L36),0) -> 0.092731377 | N41: =IFERROR((N39/M36),0) -> 0.084297372 | ... Q41: =IFERROR((Q39/P36),0) -> 0.058975339
E42: Cancel. por Inadimplência | F42: 360 | G42: 370 | H42: 329 | I42: 374 | J42: 382 | K42: 477 | L42: 527 | M42: 422 | N42: 602 | O42: 395 | P42: 377 | Q42: 299
E43: Cancel. solicitação cliente | F43: 170 | G43: 144 | H43: 120 | I43: 126 | J43: 133 | K43: 200 | L43: 343 | M43: 382 | N43: 208 | O43: 209 | P43: 198 | Q43: 250
E44: Cancel. Solicitado OPS | F44: 49 | G44: 48 | H44: 52 | I44: 63 | J44: 66 | K44: 75 | L44: 297 | M44: 217 | N44: 108 | O44: 89 | P44: 95 | Q44: 54
E45: Exclusão de dependente | F45: 8 | G45: 84 | H45: 70 | I45: 0 | J45: 0 | K45: 0 | L45: 0 | M45: 0 | N45: 0 | O45: 0 | P45: 0 | Q45: 0
E46: Falecimento | F46: 0 | G46: 0 | H46: 0 | I46: 0 | J46: 0 | K46: 0 | L46: 0 | M46: 0 | N46: 1 | O46: 0 | P46: 2 | Q46: 2
E47: Outros | F47: 10 | G47: 6 | H47: 3 | I47: 6 | J47: 12 | K47: 9 | L47: 3 | M47: 6 | N47: 21 | O47: 20 | P47: 15 | Q47: 12
E48: Faturamento Emitido | F48: 3679322.4 | G48: 3618246.6 | H48: 3761768.6 | I48: 3912829.7 | J48: 4106854.4 | K48: 4053916.5 | L48: 4551738.1 | M48: 4539856.5 | N48: 4346921.7 | O48: 4252808.7 | P48: 4139481 | Q48: 4094728.1
E49: Faturamento Recebido | F49: 3072084 | G49: 3061997.4 | H49: 3306359.3 | I49: 3238558.5 | J49: 3486976.3 | K49: 3542887.7 | L49: 3755938.1 | M49: 3952686 | N49: 3700457.5 | O49: 3679727.3 | P49: 3572907.9 | Q49: 3596745.1
E50: Inadimplência | F50: =IFERROR((1-F49/F48),0) -> 0.16504082 | G50: =IFERROR((1-G49/G48),0) -> 0.15373446 | H50: =IFERROR((1-H49/H48),0) -> 0.12106256 | I50: =IFERROR((1-I49/I48),0) -> 0.17232314 | J50: =IFERROR((1-J49/J48),0) -> 0.15093744 | K50: =IFERROR((1-K49/K48),0) -> 0.12605806 | L50: =IFERROR((1-L49/L48),0) -> 0.17483431 | M50: =IFERROR((1-M49/M48),0) -> 0.12933679 | ... Q50: =IFERROR((1-Q49/Q48),0) -> 0.12161563
...

Sheet Relatório Indicadores 23
E10: Indicador | F10: Jan | G10: Fev | H10: Mar | I10: Abr | J10: Mai | K10: Jun | L10: Jul | M10: Ago | N10: Set | O10: Out | P10: Nov | Q10: Dez
F11: 67796 | G11: =F14-G17+G28 -> 36636 | H11: =G14-H17+H28 -> 35117 | I11: =H14-I17+I28 -> 33990 | J11: =I14-J17+J28 -> 32946 | K11: =J14-K17+K28 -> 31039 | L11: =K14-L17+L28 -> 29027 | M11: =L14-M17+M28 -> 27431 | N11: =M14-N17+N28 -> 25624 | ... P11: =O14-P17+P28 -> 22245
F12: =F14-F11 -> -30195 | G12: =G14-G11 -> -80 | H12: =H14-H11 -> 2 | I12: =I14-I11 -> -30 | J12: =J14-J11 -> -105 | K12: =K14-K11 -> -4 | L12: =L14-L11 -> -11 | M12: =M14-M11 -> -276 | ... P12: =P14-P11 -> -7
E13: Meta orçada | F13: 39350.241 | G13: 39450.241 | H13: 39850.241 | I13: 40050.241 | J13: 40350.241 | K13: 40600.241 | L13: 39500.241 | M13: 40000.241 | N13: 40400.241 | O13: 40800.241 | P13: 41600.241 | Q13: 42250.241
E14: Base Vidas | F14: =SUM(F15:F16) -> 37601 | G14: =SUM(G15:G16) -> 36556 | H14: =SUM(H15:H16) -> 35119 | I14: =SUM(I15:I16) -> 33960 | J14: =SUM(J15:J16) -> 32841 | K14: =SUM(K15:K16) -> 31035 | L14: =SUM(L15:L16) -> 29016 | M14: =SUM(M15:M16) -> 27155 | ... Q14: =SUM(Q15:Q16) -> 21201
E15: Base Dental | F15: 1554 | G15: 1582 | H15: 1551 | I15: 1513 | J15: 1497 | K15: 1459 | L15: 1368 | M15: 1345 | N15: 1304 | O15: 1250 | P15: 1207 | Q15: 1170
E16: Base Saúde | F16: 36047 | G16: 34974 | H16: 33568 | I16: 32447 | J16: 31344 | K16: 29576 | L16: 27648 | M16: 25810 | N16: 24150 | O16: 22498 | P16: 21031 | Q16: 20031
E17: Vidas canceladas | F17: 1571 | G17: =SUM(G20:G24) -> 1489 | H17: =SUM(H20:H24) -> 1857 | I17: =SUM(I20:I24) -> 1461 | J17: =SUM(J20:J24) -> 1303 | K17: =SUM(K20:K24) -> 2007 | L17: =SUM(L20:L24) -> 2639 | M17: =SUM(M20:M24) -> 1912 | N17: =SUM(N20:N24) -> 1700 | ... Q17: =SUM(Q20:Q24) -> 1068
E18: Retenção | F18: 406 | G18: 221 | H18: 1583 | I18: 646 | J18: 262 | K18: 274 | L18: 578 | M18: 227 | N18: 86 | O18: 226 | P18: 196 | Q18: 90
E19: % cancelamento | F19: 0.040534613 | G19: =IFERROR(G17/F14,0) -> 0.039600011 | H19: =IFERROR(H17/G14,0) -> 0.050798774 | I19: =IFERROR(I17/H14,0) -> 0.041601412 | J19: =IFERROR(J17/I14,0) -> 0.038368669 | K19: =IFERROR(K17/J14,0) -> 0.061112634 | L19: =IFERROR(L17/K14,0) -> 0.085033027 | M19: =IFERROR(M17/L14,0) -> 0.065894679 | N19: =IFERROR(N17/M14,0) -> 0.062603572 | ... R19: =IFERROR(R17/Q14,0) -> 0
E20: Cancel. por Inadimplência | F20: 450 | G20: 389 | H20: 400 | I20: 464 | J20: 327 | K20: 331 | L20: 353 | M20: 361 | N20: 549 | O20: 384 | P20: 482 | Q20: 231
E21: Cancel. solicitação cliente | F21: 819 | G21: 802 | H21: 1042 | I21: 728 | J21: 718 | K21: 1164 | L21: 1708 | M21: 1171 | N21: 849 | O21: 978 | P21: 597 | Q21: 28
E22: Cancel. Solicitado OPS | F22: 218 | G22: 252 | H22: 357 | I22: 246 | J22: 0 | K22: 0 | L22: 520 | M22: 0 | N22: 0 | O22: 0 | P22: 0 | Q22: 0
E23: Óbito | F23: 8 | G23: 8 | H23: 4 | I23: 6 | J23: 7 | K23: 5 | L23: 9 | M23: 7 | N23: 2 | O23: 5 | P23: 6 | Q23: 0
E24: Outros | F24: 76 | G24: 38 | H24: 54 | I24: 17 | J24: 251 | K24: 507 | L24: 49 | M24: 373 | N24: 300 | O24: 310 | P24: 481 | Q24: 809
E25: Faturamento Emitido | F25: 30283887 | G25: 29226831 | H25: 29775808 | I25: 28470540 | J25: 27912180 | K25: 26912758 | L25: 27701740 | M25: 26066020 | N25: 24533308 | O25: 23577275 | P25: 22552505 | Q25: 21566158
E26: Faturamento Recebido | F26: 27909309 | G26: 26177577 | H26: 27151350 | I26: 25405490 | J26: 25323822 | K26: 24361742 | L26: 24828370 | M26: 23721421 | N26: 22432856 | O26: 21630791 | P26: 20768599 | Q26: 19720133
E27: Inadimplência do fechamento do mês | F27: =IFERROR((1-F26/F25),0) -> 0.078410613 | G27: =IFERROR((1-G26/G25),0) -> 0.10433065 | H27: =IFERROR((1-H26/H25),0) -> 0.088140589 | I27: =IFERROR((1-I26/I25),0) -> 0.1076569 | J27: =IFERROR((1-J26/J25),0) -> 0.092732215 | K27: =IFERROR((1-K26/K25),0) -> 0.094788351 | L27: =IFERROR((1-L26/L25),0) -> 0.10372525 | M27: =IFERROR((1-M26/M25),0) -> 0.089948499 | ... Q27: =IFERROR((1-Q26/Q25),0) -> 0.085598195
E28: Vendas | F28: 457 | G28: 524 | H28: 418 | I28: 332 | J28: 289 | K28: 205 | L28: 631 | M28: 327 | N28: 169 | O28: 41 | P28: 63 | Q28: 53
E29: Ticket médio | F29: =IFERROR(F25/F14,0) -> 805.40111 | G29: =IFERROR(G25/G14,0) -> 799.50845 | H29: =IFERROR(H25/H14,0) -> 847.85465 | I29: =IFERROR(I25/I14,0) -> 838.35512 | J29: =IFERROR(J25/J14,0) -> 849.9187 | K29: =IFERROR(K25/K14,0) -> 867.17441 | L29: =IFERROR(L25/L14,0) -> 954.70569 | M29: =IFERROR(M25/M14,0) -> 959.89762 | ... Q29: =IFERROR(Q25/Q14,0) -> 1017.2236
E30: Comissão Concessionárias | F30: 481797.36 | G30: 438472.98 | H30: 463109.63 | I30: 372012.98 | J30: 389753.54 | K30: 286807.47 | L30: 0 | M30: 0 | N30: 0 | O30: 0 | P30: 0 | Q30: 0
E31: Bonificação Corretores/supervisores | F31: 62176 | G31: 0 | H31: 0 | I31: 0 | J31: 0 | K31: 0 | L31: 0 | M31: 0 | N31: 0 | O31: 0 | P31: 0 | Q31: 0
F33: 10698 | G33: =F37-G40+G51 -> 11021 | H33: =G37-H40+H51 -> 11069 | I33: =H37-I40+I51 -> 11255 | J33: =I37-J40+J51 -> 11341 | K33: =J37-K40+K51 -> 11277 | L33: =K37-L40+L51 -> 10798 | M33: =L37-M40+M51 -> 10858 | N33: =M37-N40+N51 -> 10761 | ... P33: =O37-P40+P51 -> 10394
F34: =F37-F33 -> 40 | G34: =G37-G33 -> 2 | H34: =H37-H33 -> 22 | I34: =I37-I33 -> 8 | J34: =J37-J33 -> 6 | K34: =K37-K33 -> 21 | L34: =L37-L33 -> 29 | M34: =M37-M33 -> -20 | ... P34: =P37-P33 -> 25
E35: Indicador | F35: Jan | G35: Fev | H35: Mar | I35: Abr | J35: Mai | K35: Jun | L35: Jul | M35: Ago | N35: Set | O35: Out | P35: Nov | Q35: Dez
E36: Meta orçada | F36: 10878.487 | G36: 11078.487 | H36: 11329.672 | I36: 11579.672 | J36: 11829.502 | K36: 11929.502 | L36: 12933.027 | M36: 13635.424 | N36: 14087.222 | O36: 14339.666 | P36: 14594.02 | Q36: 14795.474
E37: Base Vidas | F37: =SUM(F38:F39) -> 10738 | G37: =SUM(G38:G39) -> 11023 | H37: =SUM(H38:H39) -> 11091 | I37: =SUM(I38:I39) -> 11263 | J37: =SUM(J38:J39) -> 11347 | K37: =SUM(K38:K39) -> 11298 | L37: =SUM(L38:L39) -> 10827 | M37: =SUM(M38:M39) -> 10838 | ... Q37: =SUM(Q38:Q39) -> 10350
E38: Base Dental | F38: 415 | G38: 573 | H38: 630 | I38: 662 | J38: 684 | K38: 662 | L38: 587 | M38: 448 | N38: 431 | O38: 410 | P38: 388 | Q38: 407
E39: Base Saúde | F39: 10323 | G39: 10450 | H39: 10461 | I39: 10601 | J39: 10663 | K39: 10636 | L39: 10240 | M39: 10390 | N39: 10341 | O39: 10221 | P39: 10031 | Q39: 9943
E40: Vidas canceladas | F40: 720 | G40: =SUM(G43:G47) -> 595 | H40: =SUM(H43:H47) -> 573 | I40: =SUM(I43:I47) -> 529 | J40: =SUM(J43:J47) -> 509 | K40: =SUM(K43:K47) -> 623 | L40: =SUM(L43:L47) -> 1208 | M40: =SUM(M43:M47) -> 1031 | N40: =SUM(N43:N47) -> 871 | ... Q40: =SUM(Q43:Q47) -> 527
E41: Retenção | F41: 213 | G41: 114 | H41: 192 | I41: 113 | J41: 70 | K41: 53 | L41: 155 | M41: 111 | N41: 89 | O41: 71 | P41: 105 | Q41: 62
E42: % cancelamento | F42: 0.06814955 | G42: =IFERROR(G40/F37,0) -> 0.055410691 | H42: =IFERROR(H40/G37,0) -> 0.051982219 | I42: =IFERROR(I40/H37,0) -> 0.04769633 | J42: =IFERROR(J40/I37,0) -> 0.045192222 | K42: =IFERROR(K40/J37,0) -> 0.05490438 | L42: =IFERROR(L40/K37,0) -> 0.10692158 | M42: =IFERROR(M40/L37,0) -> 0.095224901 | N42: =IFERROR(N40/M37,0) -> 0.080365381 | ... Q42: =IFERROR(Q40/P37,0) -> 0.05058067
E43: Cancel. por Inadimplência | F43: 306 | G43: 294 | H43: 316 | I43: 322 | J43: 260 | K43: 220 | L43: 275 | M43: 390 | N43: 438 | O43: 344 | P43: 337 | Q43: 277
E44: Cancel. solicitação cliente | F44: 313 | G44: 202 | H44: 200 | I44: 150 | J44: 196 | K44: 305 | L44: 713 | M44: 480 | N44: 328 | O44: 250 | P44: 166 | Q44: 8
E45: Cancel. Solicitado OPS | F45: 87 | G45: 81 | H45: 51 | I45: 57 | J45: 0 | K45: 0 | L45: 217 | M45: 0 | N45: 0 | O45: 0 | P45: 0 | Q45: 0
E46: Óbito | F46: 0 | G46: 1 | H46: 1 | I46: 0 | J46: 0 | K46: 1 | L46: 0 | M46: 3 | N46: 0 | O46: 1 | P46: 0 | Q46: 2
E47: Outros | F47: 14 | G47: 17 | H47: 5 | I47: 0 | J47: 53 | K47: 97 | L47: 3 | M47: 158 | N47: 105 | O47: 106 | P47: 103 | Q47: 240
E48: Faturamento Emitido | F48: 4073303.1 | G48: 4097778.1 | H48: 4116664.5 | I48: 4160236.5 | J48: 4199878 | K48: 4268066 | L48: 4957215.7 | M48: 4862602.8 | N48: 4765295.8 | O48: 4678540.6 | P48: 4578527.7 | Q48: 4529750.1
E49: Faturamento Recebido | F49: 3585404.1 | G49: 3437176.5 | H49: 3590883 | I49: 3431928.6 | J49: 3632212.5 | K49: 3696556.5 | L49: 4131524.7 | M49: 4164095.1 | N49: 4104221 | O49: 4075821.4 | P49: 3970420.1 | Q49: 3889603.3
E50: Inadimplência do fechamento do mês | F50: =IFERROR((1-F49/F48),0) -> 0.1197797 | G50: =IFERROR((1-G49/G48),0) -> 0.16120969 | H50: =IFERROR((1-H49/H48),0) -> 0.12772026 | I50: =IFERROR((1-I49/I48),0) -> 0.17506406 | J50: =IFERROR((1-J49/J48),0) -> 0.13516237 | K50: =IFERROR((1-K49/K48),0) -> 0.13390362 | L50: =IFERROR((1-L49/L48),0) -> 0.16656347 | M50: =IFERROR((1-M49/M48),0) -> 0.14364893 | ... Q50: =IFERROR((1-Q49/Q48),0) -> 0.14132056
...

Sheet Relatório Indicadores 24
E10: Indicador | F10: Jan | G10: Fev | H10: Mar | I10: Abr | J10: Mai | K10: Jun | L10: Jul | M10: Ago | N10: Set | O10: Out | P10: Nov | Q10: Dez
F11: 67796 | G11: 20173 | H11: =G14-H17+H28 -> 18141 | I11: =H14-I17+I28 -> 17186 | J11: =I14-J17+J28 -> 16564 | K11: =J14-K17+K28 -> 15923 | L11: =K14-L17+L28 -> 14301 | M11: =L14-M17+M28 -> 13321 | N11: =M14-N17+N28 -> 12534 | O11: =N14-O17+O28 -> 11792 | P11: =O14-P17+P28 -> 11328
F12: =F14-F11 -> -47573 | G12: 0 | H12: =H14-H11 -> -17 | I12: =I14-I11 -> -34 | J12: =J14-J11 -> -28 | K12: =K14-K11 -> -30 | L12: =L14-L11 -> -118 | M12: =M14-M11 -> -69 | N12: =N14-N11 -> -47 | O12: =O14-O11 -> -38 | P12: =P14-P11 -> -13
E13: Meta orçada | F13: 0 | G13: 0 | H13: 0 | I13: 0 | J13: 0 | K13: 0 | L13: 0 | M13: 0 | N13: 0 | O13: 0 | P13: 0 | Q13: 0
E14: Base Vidas | F14: 20223 | G14: =SUM(G15:G16) -> 19388 | H14: =SUM(H15:H16) -> 18124 | I14: =SUM(I15:I16) -> 17152 | J14: =SUM(J15:J16) -> 16536 | K14: =SUM(K15:K16) -> 15893 | L14: =SUM(L15:L16) -> 14183 | M14: =SUM(M15:M16) -> 13252 | N14: =SUM(N15:N16) -> 12487 | ... Q14: =SUM(Q15:Q16) -> 10916
E15: Base Dental | F15: 1124 | G15: 1105 | H15: 1057 | I15: 1014 | J15: 979 | K15: 949 | L15: 910 | M15: 887 | N15: 853 | O15: 840 | P15: 831 | Q15: 805
E16: Base Saúde | F16: 19099 | G16: 18283 | H16: 17067 | I16: 16138 | J16: 15557 | K16: 14944 | L16: 13273 | M16: 12365 | N16: 11634 | O16: 10914 | P16: 10484 | Q16: 10111
E17: Vidas canceladas | F17: 969 | G17: =SUM(G20:G24) -> 853 | H17: =SUM(H20:H24) -> 1282 | I17: =SUM(I20:I24) -> 948 | J17: =SUM(J20:J24) -> 594 | K17: =SUM(K20:K24) -> 620 | L17: =SUM(L20:L24) -> 1593 | M17: =SUM(M20:M24) -> 868 | N17: =SUM(N20:N24) -> 718 | ... Q17: =SUM(Q20:Q24) -> 341
E18: Retenção | F18: 287 | G18: 579 | H18: 645 | I18: 281 | J18: 238 | K18: 469 | L18: 640 | M18: 203 | N18: 264 | O18: 298 | P18: 231 | Q18: 133
E19: % cancelamento | F19: 0.025001935 | G19: 0.0030658161 | H19: =IFERROR(H17/G14,0) -> 0.066123375 | I19: =IFERROR(I17/H14,0) -> 0.052306334 | J19: =IFERROR(J17/I14,0) -> 0.03463153 | K19: =IFERROR(K17/J14,0) -> 0.037493953 | L19: =IFERROR(L17/K14,0) -> 0.10023281 | M19: =IFERROR(M17/L14,0) -> 0.061200028 | N19: =IFERROR(N17/M14,0) -> 0.054180501 | O19: =IFERROR(O17/N14,0) -> 0.056138384 | ... Q19: =IFERROR(Q17/P14,0) -> 0.030136986
E20: Cancel. por Inadimplência | F20: 210 | G20: 155 | H20: 180 | I20: 157 | J20: 114 | K20: 129 | L20: 108 | M20: 117 | N20: 193 | O20: 117 | P20: 86 | Q20: 68
E21: Cancel. solicitação cliente | F21: 580 | G21: 23 | H21: 4 | I21: 0 | J21: 196 | K21: 478 | L21: 1397 | M21: 695 | N21: 471 | O21: 538 | P21: 332 | Q21: 240
E22: Cancel. Solicitado OPS | F22: 147 | G22: 115 | H22: 215 | I22: 101 | J22: 2 | K22: 5 | L22: 83 | M22: 52 | N22: 45 | O22: 44 | P22: 6 | Q22: 24
E23: Óbito | F23: 5 | G23: 5 | H23: 6 | I23: 1 | J23: 4 | K23: 3 | L23: 2 | M23: 3 | N23: 4 | O23: 0 | P23: 0 | Q23: 6
E24: Outros | F24: 27 | G24: 555 | H24: 877 | I24: 689 | J24: 278 | K24: 5 | L24: 3 | M24: 1 | N24: 5 | O24: 2 | P24: 3 | Q24: 3
E25: Faturamento Emitido | F25: 20696311 | G25: 19861347 | H25: 19737965 | I25: 18698622 | J25: 18062551 | K25: 17530789 | L25: 18054362 | M25: 16446949 | N25: 15289253 | O25: 14764066 | P25: 14589464 | Q25: 14070981
E26: Faturamento Recebido | F26: 19080214 | G26: 18421570 | H26: 18279815 | I26: 17154897 | J26: 16886610 | K26: 16123506 | L26: 16110829 | M26: 14730990 | N26: 13787678 | O26: 13413426 | P26: 13249979 | Q26: 12766279
E27: Inadimplência do fechamento do mês | F27: 0.078086247 | G27: 0.94827108 | H27: =IFERROR((1-H26/H25),0) -> 0.073875364 | I27: =IFERROR((1-I26/I25),0) -> 0.082558242 | J27: =IFERROR((1-J26/J25),0) -> 0.065103809 | K27: =IFERROR((1-K26/K25),0) -> 0.08027494 | L27: =IFERROR((1-L26/L25),0) -> 0.10764894 | M27: =IFERROR((1-M26/M25),0) -> 0.10433297 | N27: =IFERROR((1-N26/N25),0) -> 0.098211146 | O27: =IFERROR((1-O26/O25),0) -> 0.091481544 | ... Q27: =IFERROR((1-Q26/Q25),0) -> 0.092722875
E28: Vendas | F28: 45 | G28: 34 | H28: 35 | I28: 10 | J28: 6 | K28: 7 | L28: 1 | M28: 6 | N28: 0 | O28: 6 | P28: 1 | Q28: 1
E29: Ticket médio | F29: 1023.4046 | G29: 659.02166 | H29: =IFERROR(H25/H14,0) -> 1089.0512 | I29: =IFERROR(I25/I14,0) -> 1090.1715 | J29: =IFERROR(J25/J14,0) -> 1092.3168 | K29: =IFERROR(K25/K14,0) -> 1103.051 | L29: =IFERROR(L25/L14,0) -> 1272.9579 | M29: =IFERROR(M25/M14,0) -> 1241.0919 | N29: =IFERROR(N25/N14,0) -> 1224.4137 | O29: =IFERROR(O25/O14,0) -> 1256.0887 | ... Q29: =IFERROR(Q25/Q14,0) -> 1289.0236
E30: Comissão Concessionárias | F30: 0 | G30: 0 | H30: 0 | I30: 0 | J30: 0 | K30: 0 | L30: 0 | M30: 0 | N30: 0 | O30: 0 | P30: 0 | Q30: 0
E31: Bonificação Corretores/supervisores | F31: 0 | G31: 0 | H31: 0 | I31: 0 | J31: 0 | K31: 0 | L31: 0 | M31: 0 | N31: 0 | O31: 0 | P31: 0 | Q31: 0
F33: 10698 | G33: 10487 | H33: =G37-H40+H51 -> 9913 | I33: =H37-I40+I51 -> 9656 | J33: =I37-J40+J51 -> 9506 | K33: =J37-K40+K51 -> 9391 | L33: =K37-L40+L51 -> 7916 | M33: =L37-M40+M51 -> 8857 | N33: =M37-N40+N51 -> 8447 | O33: =N37-O40+O51 -> 8232 | P33: =O37-P40+P51 -> 7971
F34: =F37-F33 -> -489 | G34: 0 | H34: =H37-H33 -> 15 | I34: =I37-I33 -> 34 | J34: =J37-J33 -> 18 | K34: =K37-K33 -> 41 | L34: =L37-L33 -> 1207 | M34: =M37-M33 -> -20 | N34: =N37-N33 -> 11 | O34: =O37-O33 -> 7 | P34: =P37-P33 -> 5
E35: Indicador | F35: Jan | G35: Fev | H35: Mar | I35: Abr | J35: Mai | K35: Jun | L35: Jul | M35: Ago | N35: Set | O35: Out | P35: Nov | Q35: Dez
E36: Meta orçada | F36: 0 | G36: 0 | H36: 0 | I36: 0 | J36: 0 | K36: 0 | L36: 0 | M36: 0 | N36: 0 | O36: 0 | P36: 0 | Q36: 0
E37: Base Vidas | F37: 10209 | G37: =SUM(G38:G39) -> 10126 | H37: =SUM(H38:H39) -> 9928 | I37: =SUM(I38:I39) -> 9690 | J37: =SUM(J38:J39) -> 9524 | K37: =SUM(K38:K39) -> 9432 | L37: =SUM(L38:L39) -> 9123 | M37: =SUM(M38:M39) -> 8837 | N37: =SUM(N38:N39) -> 8458 | ... Q37: =SUM(Q38:Q39) -> 7784
E38: Base Dental | F38: 388 | G38: 379 | H38: 379 | I38: 359 | J38: 363 | K38: 359 | L38: 375 | M38: 338 | N38: 343 | O38: 339 | P38: 328 | Q38: 330
E39: Base Saúde | F39: 9821 | G39: 9747 | H39: 9549 | I39: 9331 | J39: 9161 | K39: 9073 | L39: 8748 | M39: 8499 | N39: 8115 | O39: 7900 | P39: 7648 | Q39: 7454
E40: Vidas canceladas | F40: 532 | G40: =SUM(G43:G47) -> 484 | H40: =SUM(H43:H47) -> 544 | I40: =SUM(I43:I47) -> 622 | J40: =SUM(J43:J47) -> 455 | K40: =SUM(K43:K47) -> 571 | L40: =SUM(L43:L47) -> 2609 | M40: =SUM(M43:M47) -> 656 | N40: =SUM(N43:N47) -> 657 | ... Q40: =SUM(Q43:Q47) -> 297
E41: Retenção | F41: 92 | G41: 57 | H41: 139 | I41: 79 | J41: 48 | K41: 287 | L41: 255 | M41: 109 | N41: 65 | O41: 56 | P41: 45 | Q41: 37
E42: % cancelamento | F42: 0.050354946 | G42: 0.0023508669 | H42: =IFERROR(H40/G37,0) -> 0.053723089 | I42: =IFERROR(I40/H37,0) -> 0.062651088 | J42: =IFERROR(J40/I37,0) -> 0.046955624 | K42: =IFERROR(K40/J37,0) -> 0.059953801 | L42: =IFERROR(L40/K37,0) -> 0.27661154 | M42: =IFERROR(M40/L37,0) -> 0.071906171 | N42: =IFERROR(N40/M37,0) -> 0.074346498 | O42: =IFERROR(O40/N37,0) -> 0.049538898 | ... Q42: =IFERROR(Q40/P37,0) -> 0.03723671
E43: Cancel. por Inadimplência | F43: 251 | G43: 223 | H43: 229 | I43: 246 | J43: 202 | K43: 202 | L43: 196 | M43: 217 | N43: 321 | O43: 188 | P43: 177 | Q43: 122
E44: Cancel. solicitação cliente | F44: 229 | G44: 9 | H44: 1 | I44: 0 | J44: 89 | K44: 258 | L44: 1079 | M44: 327 | N44: 213 | O44: 186 | P44: 156 | Q44: 136
E45: Cancel. Solicitado OPS | F45: 51 | G45: 55 | H45: 52 | I45: 54 | J45: 46 | K45: 57 | L45: 142 | M45: 90 | N45: 65 | O45: 43 | P45: 55 | Q45: 38
E46: Óbito | F46: 0 | G46: 1 | H46: 2 | I46: 0 | J46: 0 | K46: 0 | L46: 0 | M46: 1 | N46: 0 | O46: 0 | P46: 0 | Q46: 1
E47: Outros | F47: 1 | G47: 196 | H47: 260 | I47: 322 | J47: 118 | K47: 54 | L47: 1192 | M47: 21 | N47: 58 | O47: 2 | P47: 3 | Q47: 0
E48: Faturamento Emitido | F48: 4468101.8 | G48: 4417062.2 | H48: 4364064.5 | I48: 4261267 | J48: 4157318.8 | K48: 4114843.1 | L48: 4704675.8 | M48: 4590624.7 | N48: 4388274.1 | O48: 4273680.8 | P48: 4119052.6 | Q48: 4015079.1
E49: Faturamento Recebido | F49: 3896540.9 | G49: 3877393.6 | H49: 3798805.2 | I49: 3728914.9 | J49: 3742180.8 | K49: 3588679.4 | L49: 4044753.8 | M49: 3990550.5 | N49: 3833540.5 | O49: 3827804.5 | P49: 3632552.4 | Q49: 3504147.5
E50: Inadimplência do fechamento do mês | F50: 0.1279203 | G50: 0.94202669 | H50: =IFERROR((1-H49/H48),0) -> 0.12952587 | I50: =IFERROR((1-I49/I48),0) -> 0.12492814 | J50: =IFERROR((1-J49/J48),0) -> 0.099857139 | K50: =IFERROR((1-K49/K48),0) -> 0.12786969 | L50: =IFERROR((1-L49/L48),0) -> 0.14026939 | M50: =IFERROR((1-M49/M48),0) -> 0.13071732 | N50: =IFERROR((1-N49/N48),0) -> 0.12641271 | O50: =IFERROR((1-O49/O48),0) -> 0.10433074 | ... Q50: =IFERROR((1-Q49/Q48),0) -> 0.12725321
...

Sheet Relatório Indicadores 25
E10: Indicador | F10: Jan | G10: Fev | H10: Mar | I10: Abr | J10: Mai | K10: Jun | L10: Jul | M10: Ago | N10: Set | O10: Out | P10: Nov | Q10: Dez
F11: 67796 | G11: 20173 | H11: =G14-H17+H28 -> 9744 | I11: =H14-I17+I28 -> 9002 | J11: =I14-J17+J28 -> 8712 | K11: =J14-K17+K28 -> 8406 | L11: =K14-L17+L28 -> 7993 | M11: =L14-M17+M28 -> 7601 | N11: =M14-N17+N28 -> 7062 | O11: =N14-O17+O28 -> 6502 | P11: =O14-P17+P28 -> 6091
F12: =F14-F11 -> -57287 | G12: 0 | H12: =H14-H11 -> -23 | I12: =I14-I11 -> -14 | J12: =J14-J11 -> -12 | K12: =K14-K11 -> 2 | L12: =L14-L11 -> -50 | M12: =M14-M11 -> -49 | N12: =N14-N11 -> -47 | O12: =O14-O11 -> -9 | P12: =P14-P11 -> -39
E13: Meta orçada | F13: 0 | G13: 0 | H13: 0 | I13: 0 | J13: 0 | K13: 0 | L13: 0 | M13: 0 | N13: 0 | O13: 0 | P13: 0 | Q13: 0
E14: Base Vidas | F14: =SUM(F15:F16) -> 10509 | G14: =SUM(G15:G16) -> 10127 | H14: =SUM(H15:H16) -> 9721 | I14: =SUM(I15:I16) -> 8988 | J14: =SUM(J15:J16) -> 8700 | K14: 8408 | L14: =SUM(L15:L16) -> 7943 | M14: =SUM(M15:M16) -> 7552 | N14: =SUM(N15:N16) -> 7015 | O14: =SUM(O15:O16) -> 6493 | P14: =SUM(P15:P16) -> 6052 | Q14: =SUM(Q15:Q16) -> 5728
E15: Base Dental | F15: 774 | G15: 728 | H15: 700 | I15: 680 | J15: 667 | K15: 644 | L15: 629 | M15: 602 | N15: 573 | O15: 532 | P15: 510 | Q15: 497
E16: Base Saúde | F16: 9735 | G16: 9399 | H16: 9021 | I16: 8308 | J16: 8033 | K16: 7764 | L16: 7314 | M16: 6950 | N16: 6442 | O16: 5961 | P16: 5542 | Q16: 5231
E17: Vidas canceladas | F17: =SUM(F20:F24) -> 377 | G17: =SUM(G20:G24) -> 373 | H17: =SUM(H20:H24) -> 386 | I17: =SUM(I20:I24) -> 719 | J17: =SUM(J20:J24) -> 276 | K17: 294 | L17: =SUM(L20:L24) -> 415 | M17: =SUM(M20:M24) -> 342 | N17: =SUM(N20:N24) -> 490 | O17: =SUM(O20:O24) -> 513 | P17: =SUM(P20:P24) -> 402 | Q17: =SUM(Q20:Q24) -> 296
E18: Retenção | F18: 262 | G18: 213 | H18: 378 | I18: 176 | J18: 176 | K18: 367 | L18: 257 | M18: 193 | N18: 202 | O18: 163 | P18: 86 | Q18: 87
E19: % cancelamento | F19: =IFERROR(F17/'Relatório Indicadores 24'!Q14,0) -> 0.03453646 | G19: =IFERROR(G17/F14,0) -> 0.035493387 | H19: =IFERROR(H17/G14,0) -> 0.038115928 | I19: =IFERROR((I17-333)/H14,0) -> 0.039707849 | J19: =IFERROR(J17/I14,0) -> 0.03070761 | K19: 0.033793103 | L19: =IFERROR(L17/K14,0) -> 0.049357755 | M19: =IFERROR(M17/L14,0) -> 0.04305678 | N19: =IFERROR(N17/M14,0) -> 0.064883475 | O19: =IFERROR(O17/N14,0) -> 0.073129009 | P19: =IFERROR(P17/O14,0) -> 0.061912829 | Q19: =IFERROR(Q17/P14,0) -> 0.048909451
E20: Cancel. por Inadimplência | F20: 66 | G20: 54 | H20: 56 | I20: 52 | J20: 47 | K20: 54 | L20: 35 | M20: 41 | N20: 63 | O20: 37 | P20: 48 | Q20: 26
E21: Cancel. solicitação cliente | F21: 291 | G21: 306 | H21: 313 | I21: 285 | J21: 205 | K21: 215 | L21: 346 | M21: 245 | N21: 359 | O21: 422 | P21: 277 | Q21: 222
E22: Cancel. Solicitado OPS | F22: 15 | G22: 9 | H22: 12 | I22: 31 | J22: 14 | K22: 20 | L22: 29 | M22: 55 | N22: 65 | O22: 48 | P22: 74 | Q22: 45
E23: Óbito | F23: 4 | G23: 3 | H23: 2 | I23: 7 | J23: 10 | K23: 4 | L23: 3 | M23: 1 | N23: 2 | O23: 5 | P23: 1 | Q23: 3
E24: Outros | F24: 1 | G24: 1 | H24: 3 | I24: 344 | J24: 0 | K24: 1 | L24: 2 | M24: 0 | N24: 1 | O24: 1 | P24: 2 | Q24: 0
E25: Faturamento Emitido | F25: 13736662 | G25: 13238552 | H25: 13162982 | I25: 12379630 | J25: 11969434 | K25: 11591490 | L25: 11838452 | M25: 11179718 | N25: 10395755 | O25: 9774591.4 | P25: 9113933.5 | Q25: 8584005.3
E26: Faturamento Recebido | F26: 12590544 | G26: 12052757 | H26: 12024623 | I26: 11440534 | J26: 11177452 | K26: 10730406 | L26: 11027553 | M26: 10379717 | N26: 9652394.9 | O26: 8998008.6 | P26: 8379575.7 | Q26: 7959330.7
E27: Inadimplência do fechamento do mês | F27: =IFERROR((1-F26/F25),0) -> 0.083434986 | G27: =IFERROR((1-G26/G25),0) -> 0.089571342 | H27: =IFERROR((1-H26/H25),0) -> 0.086481825 | I27: =IFERROR((1-I26/I25),0) -> 0.075858225 | J27: =IFERROR((1-J26/J25),0) -> 0.06616704 | K27: 0.074285907 | L27: =IFERROR((1-L26/L25),0) -> 0.068497044 | M27: =IFERROR((1-M26/M25),0) -> 0.071558239 | N27: =IFERROR((1-N26/N25),0) -> 0.071506153 | O27: =IFERROR((1-O26/O25),0) -> 0.079449133 | P27: =IFERROR((1-P26/P25),0) -> 0.080575286 | Q27: =IFERROR((1-Q26/Q25),0) -> 0.072771929
E28: Vendas | F28: 0 | G28: 3 | H28: 3 | I28: 0 | J28: 0 | K28: 0 | L28: 0 | M28: 0 | N28: 0 | O28: 0 | P28: 0 | Q28: 0
E29: Ticket médio | F29: =IFERROR(F25/F14,0) -> 1307.1331 | G29: =IFERROR(G25/G14,0) -> 1307.2531 | H29: =IFERROR(H25/H14,0) -> 1354.0769 | I29: =IFERROR(I25/I14,0) -> 1377.351 | J29: =IFERROR(J25/J14,0) -> 1375.7971 | K29: 1378.6263 | L29: =IFERROR(L25/L14,0) -> 1490.4258 | M29: =IFERROR(M25/M14,0) -> 1480.3652 | N29: =IFERROR(N25/N14,0) -> 1481.9323 | O29: =IFERROR(O25/O14,0) -> 1505.4045 | P29: =IFERROR(P25/P14,0) -> 1505.9375 | Q29: =IFERROR(Q25/Q14,0) -> 1498.6043
E30: Comissão Concessionárias | F30: 0 | G30: 0 | H30: 0 | I30: 0 | J30: 0 | K30: 0 | L30: 0 | M30: 0 | N30: 0 | O30: 0 | P30: 0 | Q30: 0
E31: Bonificação Corretores/supervisores | F31: 0 | G31: 0 | H31: 0 | I31: 0 | J31: 0 | K31: 0 | L31: 0 | M31: 0 | N31: 0 | O31: 0 | P31: 0 | Q31: 0
F33: 10698 | G33: 10487 | H33: =G37-H40+H51 -> 7095 | I33: =H37-I40+I51 -> 6916 | J33: =I37-J40+J51 -> 6815 | K33: 6631 | L33: =K37-L40+L51 -> 6180 | M33: =L37-M40+M51 -> 5857 | N33: =M37-N40+N51 -> 5907 | O33: =N37-O40+O51 -> 5880 | P33: =O37-P40+P51 -> 5901
F34: =F37-F33 -> -3116 | G34: 0 | H34: =H37-H33 -> 9 | I34: =I37-I33 -> -3 | J34: =J37-J33 -> 5 | K34: -3 | L34: =L37-L33 -> -17 | M34: =M37-M33 -> -79 | N34: =N37-N33 -> -32 | O34: =O37-O33 -> 6 | P34: =P37-P33 -> 2
E35: Indicador | F35: Jan | G35: Fev | H35: Mar | I35: Abr | J35: Mai | K35: Jun | L35: Jul | M35: Ago | N35: Set | O35: Out | P35: Nov | Q35: Dez
E36: Meta orçada | F36: 0 | G36: 0 | H36: 0 | I36: 0 | J36: 0 | K36: 0 | L36: 0 | M36: 0 | N36: 0 | O36: 0 | P36: 0 | Q36: 0
E37: Base Vidas | F37: =SUM(F38:F39) -> 7582 | G37: =SUM(G38:G39) -> 7314 | H37: =SUM(H38:H39) -> 7104 | I37: =SUM(I38:I39) -> 6913 | J37: =SUM(J38:J39) -> 6820 | K37: 6628 | L37: =SUM(L38:L39) -> 6163 | M37: =SUM(M38:M39) -> 5778 | N37: =SUM(N38:N39) -> 5875 | O37: =SUM(O38:O39) -> 5886 | P37: =SUM(P38:P39) -> 5903 | Q37: =SUM(Q38:Q39) -> 5862
E38: Base Dental | F38: 325 | G38: 317 | H38: 308 | I38: 301 | J38: 306 | K38: 304 | L38: 286 | M38: 275 | N38: 295 | O38: 302 | P38: 310 | Q38: 317
E39: Base Saúde | F39: 7257 | G39: 6997 | H39: 6796 | I39: 6612 | J39: 6514 | K39: 6324 | L39: 5877 | M39: 5503 | N39: 5580 | O39: 5584 | P39: 5593 | Q39: 5545
E40: Vidas canceladas | F40: =SUM(F43:F47) -> 283 | G40: =SUM(G43:G47) -> 338 | H40: =SUM(H43:H47) -> 293 | I40: =SUM(I43:I47) -> 327 | J40: =SUM(J43:J47) -> 358 | K40: 318 | L40: =SUM(L43:L47) -> 520 | M40: =SUM(M43:M47) -> 462 | N40: =SUM(N43:N47) -> 405 | O40: =SUM(O43:O47) -> 313 | P40: =SUM(P43:P47) -> 270 | Q40: =SUM(Q43:Q47) -> 278
E41: Retenção | F41: 61 | G41: 65 | H41: 60 | I41: 69 | J41: 40 | K41: 124 | L41: 128 | M41: 63 | N41: 49 | O41: 22 | P41: 51 | Q41: 8
E42: % cancelamento | F42: =IFERROR(F40/'Relatório Indicadores 24'!Q37,0) -> 0.036356629 | G42: =IFERROR(G40/F37,0) -> 0.044579267 | H42: =IFERROR(H40/G37,0) -> 0.040060159 | I42: =IFERROR(I40/H37,0) -> 0.046030405 | J42: =IFERROR(J40/I37,0) -> 0.051786489 | K42: 0.046627566 | L42: =IFERROR(L40/K37,0) -> 0.078455039 | M42: =IFERROR(M40/L37,0) -> 0.074963492 | N42: =IFERROR(N40/M37,0) -> 0.070093458 | O42: =IFERROR(O40/N37,0) -> 0.053276596 | P42: =IFERROR(P40/O37,0) -> 0.04587156 | Q42: =IFERROR(Q40/P37,0) -> 0.047094698
E43: Cancel. por Inadimplência | F43: 113 | G43: 122 | H43: 121 | I43: 133 | J43: 85 | K43: 97 | L43: 102 | M43: 110 | N43: 127 | O43: 113 | P43: 96 | Q43: 89
E44: Cancel. solicitação cliente | F44: 147 | G44: 152 | H44: 136 | I44: 145 | J44: 220 | K44: 160 | L44: 394 | M44: 285 | N44: 236 | O44: 157 | P44: 145 | Q44: 161
E45: Cancel. Solicitado OPS | F45: 23 | G45: 58 | H45: 22 | I45: 25 | J45: 48 | K45: 50 | L45: 19 | M45: 65 | N45: 39 | O45: 39 | P45: 17 | Q45: 28
E46: Óbito | F46: 0 | G46: 2 | H46: 0 | I46: 0 | J46: 0 | K46: 0 | L46: 0 | M46: 0 | N46: 3 | O46: 3 | P46: 1 | Q46: 0
E47: Outros | F47: 0 | G47: 4 | H47: 14 | I47: 24 | J47: 5 | K47: 11 | L47: 5 | M47: 2 | N47: 0 | O47: 1 | P47: 11 | Q47: 0
E48: Faturamento Emitido | F48: 3915907 | G48: 3780812.6 | H48: 3674762.8 | I48: 3586734.4 | J48: 3516427.9 | K48: 3424742.6 | L48: 3764841.7 | M48: 3449696.9 | N48: 3480852.4 | O48: 3477161.8 | P48: 3444912.6 | Q48: 3380610.4
E49: Faturamento Recebido | F49: 3522388.2 | G49: 3351755.9 | H49: 3333928.2 | I49: 3167262.2 | J49: 3165712.7 | K49: 3006320.4 | L49: 3355143.5 | M49: 3075206.6 | N49: 3132278.7 | O49: 3119898.9 | P49: 3045404.7 | Q49: 3037732.7
E50: Inadimplência do fechamento do mês | F50: =IFERROR((1-F49/F48),0) -> 0.10049239 | G50: =IFERROR((1-G49/G48),0) -> 0.11348266 | H50: =IFERROR((1-H49/H48),0) -> 0.092750087 | I50: =IFERROR((1-I49/I48),0) -> 0.116951 | J50: =IFERROR((1-J49/J48),0) -> 0.099736215 | K50: 0.12217624 | L50: =IFERROR((1-L49/L48),0) -> 0.10882215 | M50: =IFERROR((1-M49/M48),0) -> 0.10855743 | N50: =IFERROR((1-N49/N48),0) -> 0.10014035 | O50: =IFERROR((1-O49/O48),0) -> 0.10274555 | P50: =IFERROR((1-P49/P48),0) -> 0.11597043 | Q50: =IFERROR((1-Q49/Q48),0) -> 0.10142476
...

Sheet Relatório Indicadores 26
E10: Indicador | F10: Jan | G10: Fev | H10: Mar | I10: Abr | J10: Mai | K10: Jun | L10: Jul | M10: Ago | N10: Set | O10: Out | P10: Nov | Q10: Dez
F11: 67796 | G11: 20173 | H11: =G14-H17+H28 -> 4624 | I11: =H14-I17+I28 -> 4310 | J11: =I14-J17+J28 -> 4173 | K11: =J14-K17+K28 -> 4157 | L11: =K14-L17+L28 -> 4153 | M11: =L14-M17+M28 -> 0 | N11: =M14-N17+N28 -> 0 | O11: =N14-O17+O28 -> 0 | P11: =O14-P17+P28 -> 0
F12: =F14-F11 -> -62441 | G12: 0 | H12: =H14-H11 -> -81 | I12: =I14-I11 -> -9 | J12: =J14-J11 -> -2 | K12: =K14-K11 -> -4 | L12: =L14-L11 -> -4153 | M12: =M14-M11 -> 0 | N12: =N14-N11 -> 0 | O12: =O14-O11 -> 0 | P12: =P14-P11 -> 0
E13: Meta orçada | F13: 0 | G13: 0 | H13: 0 | I13: 0 | J13: 0 | K13: 0 | L13: 0 | M13: 0 | N13: 0 | O13: 0 | P13: 0 | Q13: 0
E14: Base Vidas | F14: =SUM(F15:F16) -> 5355 | G14: 4966 | H14: =SUM(H15:H16) -> 4543 | I14: =SUM(I15:I16) -> 4301 | J14: =SUM(J15:J16) -> 4171 | K14: =SUM(K15:K16) -> 4153 | L14: =SUM(L15:L16) -> 0 | M14: =SUM(M15:M16) -> 0 | N14: =SUM(N15:N16) -> 0 | O14: =SUM(O15:O16) -> 0 | ... Q14: =SUM(Q15:Q16) -> 0
E15: Base Dental | F15: 462 | G15: 435 | H15: 422 | I15: 409 | J15: 402 | K15: 402 | L15: 0 | M15: 0 | N15: 0 | O15: 0 | P15: 0 | Q15: 0
E16: Base Saúde | F16: 4893 | G16: 4531 | H16: 4121 | I16: 3892 | J16: 3769 | K16: 3751 | L16: 0 | M16: 0 | N16: 0 | O16: 0 | P16: 0 | Q16: 0
E17: Vidas canceladas | F17: =SUM(F20:F24) -> 336 | G17: 312 | H17: =SUM(H20:H24) -> 342 | I17: =SUM(I20:I24) -> 233 | J17: =SUM(J20:J24) -> 128 | K17: =SUM(K20:K24) -> 14 | L17: =SUM(L20:L24) -> 0 | M17: =SUM(M20:M24) -> 0 | N17: =SUM(N20:N24) -> 0 | O17: =SUM(O20:O24) -> 0 | ... Q17: =SUM(Q20:Q24) -> 0
E18: Retenção | F18: 119 | G18: 72 | H18: 92 | I18: 84 | J18: 67 | K18: 18 | L18: 0 | M18: 0 | N18: 0 | O18: 0 | P18: 0 | Q18: 0
E19: % cancelamento | F19: =IFERROR(F17/'Relatório Indicadores 25'!Q14,0) -> 0.058659218 | G19: =IFERROR(G17/F14,0) -> 0.058263305 | H19: =IFERROR(H17/G14,0) -> 0.068868304 | I19: =IFERROR(I17/H14,0) -> 0.051287695 | J19: =IFERROR(J17/I14,0) -> 0.029760521 | K19: =IFERROR(K17/J14,0) -> 0.0033565092 | L19: =IFERROR(L17/K14,0) -> 0 | M19: =IFERROR(M17/L14,0) -> 0 | N19: =IFERROR(N17/M14,0) -> 0 | ... Q19: =IFERROR(Q17/P14,0) -> 0
E20: Cancel. por Inadimplência | F20: 43 | G20: 23 | H20: 43 | I20: 41 | J20: 27 | K20: 0 | L20: 0 | M20: 0 | N20: 0 | O20: 0 | P20: 0 | Q20: 0
E21: Cancel. solicitação cliente | F21: 279 | G21: 266 | H21: 220 | I21: 144 | J21: 78 | K21: 13 | L21: 0 | M21: 0 | N21: 0 | O21: 0 | P21: 0 | Q21: 0
E22: Cancel. Solicitado OPS | F22: 10 | G22: 19 | H22: 78 | I22: 47 | J22: 20 | K22: 0 | L22: 0 | M22: 0 | N22: 0 | O22: 0 | P22: 0 | Q22: 0
E23: Óbito | F23: 4 | G23: 1 | H23: 1 | I23: 1 | J23: 3 | K23: 0 | L23: 0 | M23: 0 | N23: 0 | O23: 0 | P23: 0 | Q23: 0
E24: Outros | F24: 0 | G24: 3 | H24: 0 | I24: 0 | J24: 0 | K24: 1 | L24: 0 | M24: 0 | N24: 0 | O24: 0 | P24: 0 | Q24: 0
E25: Faturamento Emitido | F25: 8150226.9 | G25: 7422111.8 | H25: 6707545.1 | I25: 6366978.8 | J25: 6110570 | K25: 4262384.6 | L25: 0 | M25: 0 | N25: 0 | O25: 0 | P25: 0 | Q25: 0
E26: Faturamento Recebido | F26: 7487330.5 | G26: 6713587.9 | H26: 6225576.7 | I26: 5888138 | J26: 5692769.5 | K26: 1782358.3 | L26: 0 | M26: 0 | N26: 0 | O26: 0 | P26: 0 | Q26: 0
E27: Inadimplência do fechamento do mês | F27: =IFERROR((1-F26/F25),0) -> 0.081334712 | G27: 0.095461235 | H27: =IFERROR((1-H26/H25),0) -> 0.071854667 | I27: =IFERROR((1-I26/I25),0) -> 0.07520691 | J27: =IFERROR((1-J26/J25),0) -> 0.068373421 | K27: =IFERROR((1-K26/K25),0) -> 0.58184011 | L27: =IFERROR((1-L26/L25),0) -> 0 | M27: =IFERROR((1-M26/M25),0) -> 0 | N27: =IFERROR((1-N26/N25),0) -> 0 | O27: =IFERROR((1-O26/O25),0) -> 0 | ... Q27: =IFERROR((1-Q26/Q25),0) -> 0
E28: Vendas | F28: 0 | G28: 0 | H28: 0 | I28: 0 | J28: 0 | K28: 0 | L28: 0 | M28: 0 | N28: 0 | O28: 0 | P28: 0 | Q28: 0
E29: Ticket médio | F29: =IFERROR(F25/F14,0) -> 1521.9845 | G29: 1494.5855 | H29: =IFERROR(H25/H14,0) -> 1476.4572 | I29: =IFERROR(I25/I14,0) -> 1480.3485 | J29: =IFERROR(J25/J14,0) -> 1465.0132 | K29: =IFERROR(K25/K14,0) -> 1026.3387 | L29: =IFERROR(L25/L14,0) -> 0 | M29: =IFERROR(M25/M14,0) -> 0 | N29: =IFERROR(N25/N14,0) -> 0 | O29: =IFERROR(O25/O14,0) -> 0 | ... Q29: =IFERROR(Q25/Q14,0) -> 0
E30: Comissão Concessionárias | F30: 0 | G30: 0 | H30: 0 | I30: 0 | J30: 0 | K30: 0 | L30: 0 | M30: 0 | N30: 0 | O30: 0 | P30: 0 | Q30: 0
E31: Bonificação Corretores/supervisores | F31: 0 | G31: 0 | H31: 0 | I31: 0 | J31: 0 | K31: 0 | L31: 0 | M31: 0 | N31: 0 | O31: 0 | P31: 0 | Q31: 0
F33: 10698 | G33: 10487 | H33: =G37-H40+H51 -> 5257 | I33: =H37-I40+I51 -> 5059 | J33: =I37-J40+J51 -> 4883 | K33: 6631 | L33: =K37-L40+L51 -> 4878 | M33: =L37-M40+M51 -> 0 | N33: =M37-N40+N51 -> 0 | O33: =N37-O40+O51 -> 0 | P33: =O37-P40+P51 -> 0
F34: =F37-F33 -> -4995 | G34: 0 | H34: =H37-H33 -> -9 | I34: =I37-I33 -> 3 | J34: =J37-J33 -> 1 | K34: -3 | L34: =L37-L33 -> -4878 | M34: =M37-M33 -> 0 | N34: =N37-N33 -> 0 | O34: =O37-O33 -> 0 | P34: =P37-P33 -> 0
E35: Indicador | F35: Jan | G35: Fev | H35: Mar | I35: Abr | J35: Mai | K35: Jun | L35: Jul | M35: Ago | N35: Set | O35: Out | P35: Nov | Q35: Dez
E36: Meta orçada | F36: 0 | G36: 0 | H36: 0 | I36: 0 | J36: 0 | K36: 0 | L36: 0 | M36: 0 | N36: 0 | O36: 0 | P36: 0 | Q36: 0
E37: Base Vidas | F37: =SUM(F38:F39) -> 5703 | G37: =SUM(G38:G39) -> 5498 | H37: =SUM(H38:H39) -> 5248 | I37: =SUM(I38:I39) -> 5062 | J37: =SUM(J38:J39) -> 4884 | K37: =SUM(K38:K39) -> 4878 | L37: =SUM(L38:L39) -> 0 | M37: =SUM(M38:M39) -> 0 | ... Q37: =SUM(Q38:Q39) -> 0
E38: Base Dental | F38: 322 | G38: 317 | H38: 308 | I38: 302 | J38: 294 | K38: 294 | L38: 0 | M38: 0 | N38: 0 | O38: 0 | P38: 0 | Q38: 0
E39: Base Saúde | F39: 5381 | G39: 5181 | H39: 4940 | I39: 4760 | J39: 4590 | K39: 4584 | L39: 0 | M39: 0 | N39: 0 | O39: 0 | P39: 0 | Q39: 0
E40: Vidas canceladas | F40: =SUM(F43:F47) -> 252 | G40: =SUM(G43:G47) -> 227 | H40: =SUM(H43:H47) -> 249 | I40: =SUM(I43:I47) -> 191 | J40: =SUM(J43:J47) -> 186 | K40: =SUM(K43:K47) -> 17 | L40: =SUM(L43:L47) -> 0 | M40: =SUM(M43:M47) -> 0 | ... Q40: =SUM(Q43:Q47) -> 0
E41: Retenção | F41: 4 | G41: 197 | H41: 8 | I41: 11 | J41: 5 | K41: 1 | L41: 0 | M41: 0 | N41: 0 | O41: 0 | P41: 0 | Q41: 0
E42: % cancelamento | F42: =IFERROR(F40/'Relatório Indicadores 25'!Q37,0) -> 0.042988741 | G42: =IFERROR(G40/F37,0) -> 0.039803612 | H42: =IFERROR(H40/G37,0) -> 0.045289196 | I42: =IFERROR(I40/H37,0) -> 0.036394817 | J42: =IFERROR(J40/I37,0) -> 0.03674437 | K42: =IFERROR(K40/J37,0) -> 0.0034807535 | L42: =IFERROR(L40/K37,0) -> 0 | M42: =IFERROR(M40/L37,0) -> 0 | N42: =IFERROR(N40/M37,0) -> 0 | ... Q42: =IFERROR(Q40/P37,0) -> 0
E43: Cancel. por Inadimplência | F43: 90 | G43: 81 | H43: 101 | I43: 81 | J43: 78 | K43: 0 | L43: 0 | M43: 0 | N43: 0 | O43: 0 | P43: 0 | Q43: 0
E44: Cancel. solicitação cliente | F44: 115 | G44: 101 | H44: 99 | I44: 82 | J44: 81 | K44: 17 | L44: 0 | M44: 0 | N44: 0 | O44: 0 | P44: 0 | Q44: 0
E45: Cancel. Solicitado OPS | F45: 41 | G45: 40 | H45: 47 | I45: 27 | J45: 25 | K45: 0 | L45: 0 | M45: 0 | N45: 0 | O45: 0 | P45: 0 | Q45: 0
E46: Óbito | F46: 2 | G46: 0 | H46: 0 | I46: 0 | J46: 1 | K46: 0 | L46: 0 | M46: 0 | N46: 0 | O46: 0 | P46: 0 | Q46: 0
E47: Outros | F47: 4 | G47: 5 | H47: 2 | I47: 1 | J47: 1 | K47: 0 | L47: 0 | M47: 0 | N47: 0 | O47: 0 | P47: 0 | Q47: 0
E48: Faturamento Emitido | F48: 3270420.9 | G48: 3163802.3 | H48: 3017591.5 | I48: 2920828.4 | J48: 2834191.2 | K48: 1682803 | L48: 0 | M48: 0 | N48: 0 | O48: 0 | P48: 0 | Q48: 0
E49: Faturamento Recebido | F49: 2962640.3 | G49: 2820709.5 | H49: 2718474.1 | I49: 2644374 | J49: 2601223.6 | K49: 778010.03 | L49: 0 | M49: 0 | N49: 0 | O49: 0 | P49: 0 | Q49: 0
E50: Inadimplência do fechamento do mês | F50: =IFERROR((1-F49/F48),0) -> 0.094110389 | G50: =IFERROR((1-G49/G48),0) -> 0.1084432 | H50: =IFERROR((1-H49/H48),0) -> 0.099124548 | I50: =IFERROR((1-I49/I48),0) -> 0.094649304 | J50: =IFERROR((1-J49/J48),0) -> 0.082198961 | K50: =IFERROR((1-K49/K48),0) -> 0.53767017 | L50: =IFERROR((1-L49/L48),0) -> 0 | M50: =IFERROR((1-M49/M48),0) -> 0 | ... Q50: =IFERROR((1-Q49/Q48),0) -> 0
...
